 * Serving Flask app 'app'
 * Debug mode: on
[31m[1mWARNING: This is a development server. Do not use it in a production deployment. Use a production WSGI server instead.[0m
 * Running on http://127.0.0.1:5000
[33mPress CTRL+C to quit[0m
 * Restarting with stat
 * Debugger is active!
 * Debugger PIN: 818-032-705
Traceback (most recent call last):
  File "/Users/user2/autods_fresh/app.py", line 37, in <module>
    app.run(debug=True)
  File "/Users/user2/autods_fresh/venv/lib/python3.9/site-packages/flask/app.py", line 662, in run
    run_simple(t.cast(str, host), port, self, **options)
  File "/Users/user2/autods_fresh/venv/lib/python3.9/site-packages/werkzeug/serving.py", line 1115, in run_simple
    run_with_reloader(
  File "/Users/user2/autods_fresh/venv/lib/python3.9/site-packages/werkzeug/_reloader.py", line 459, in run_with_reloader
    ensure_echo_on()
  File "/Users/user2/autods_fresh/venv/lib/python3.9/site-packages/werkzeug/_reloader.py", line 439, in ensure_echo_on
    termios.tcsetattr(sys.stdin, termios.TCSANOW, attributes)
termios.error: (4, 'Interrupted system call')
/Library/Developer/CommandLineTools/Library/Frameworks/Python3.framework/Versions/3.9/lib/python3.9/multiprocessing/resource_tracker.py:216: UserWarning: resource_tracker: There appear to be 1 leaked semaphore objects to clean up at shutdown
  warnings.warn('resource_tracker: There appear to be %d '
